# 예외처리(2)

---

### 5. 예외의 발생과 catch블럭

**catch블럭은 괄호()와 블럭{} 두 부분으로 나눠져 있는데, 괄호()내에는 처리하고자 하는 예외와 같은 타입의 참조변수 하나를 선언해야한다.** 

예외가 발생하면, 발생한 예외에 해당하는 클래스의 인스턴스가 만들어 진다. 예외가 발생한 문장이 try블럭에 포함되어 있다면, 이 예외를  처리할 수 있는 catch블럭이 있는지 찾게 된다.

첫 번째 catch블럭부터 차례대로 내려가면서 catch블럭의 괄호()내에 선언된 참조변수의 종류와 생성된 예외클래스의 인스턴스에 instanceof연산자를 이용해서 검사하게 되는데, 검사결과가 true인 catch블럭을 찾게될때까지 검사는 계속된다.

만약 true인 catch블럭을 발견하게되면, 예외를 처리하고 try-catch문을 빠져나가지만 만약 없으면, 예외를 처리하지 못한다.

```java
class ExceptionEx6 {
  public static void main(String args[]) {
    System.out.println(1);
    System.out.println(2);
    try {
      System.out.println(3);
    	System.out.println(0/0);
    	System.out.println(4);
    } catch(Exception e) {
      System.out.println(5);
    }
    System.out.println(6);
  }
}
/*
출력 :
1
2
3
5
6
*/
```

위 코드를 보면 Exception은 모든 Exception클래스들의 부모이므로 모든 Exception이 instanceof를 했을 때 true가 되어 Exceptio n클래스타입의 참조변수를 선언한 catch블럭의 문장들이 수행되고 예외는 처리되는 것이다.

```java
class ExceptionEx7 {
  public static void main(String args[]) {
    System.out.println(1);
    System.out.println(2);
    try {
      System.out.println(3);
    	System.out.println(0/0);
    	System.out.println(4);
    } catch (ArithmeticException ae) {
      if(ae instanceof ArithmeticException) 
        System.out.println("true");
      System.out.println("ArithmeticException");
    } catch (Exception e) {
      System.out.println('Exception');
    }
    System.out.println(6);
  }
}
/*
출력 :
1
2
3
true
ArithmeticException
6
*/
```

위 코드는 try-catch문에서 catch를 두번사용하여 예외처리를 한 코드이다. 이 코드에서 출력결과를 보면 알 수 있듯 두번째 catch문을 실행하지 않았다. 그 이유는 try에서 발견된 예외를 해결하기 위하여 catch블럭을 처음부터 확인하는데 이때 첫번째에서 예외가 true라면,  뒤 catch들은 실행하지않는다.

그러나 위 코드에서 만약 에러가 ArithmeticException이 아니라면, 첫 번째 catch문은 건너뛰고 Exception에서 걸러져 예외 처리가 될 것이다.

**1. printStackTrace()와 getMessage()**

예외가 발생했을 때 생성되는 예외 클래스의 인스턴스에는 발생한 예외에 대한 정보가 담겨 있으,며, getMessage()와 printStackTrace()를 통해 이 정보들을 얻을 수 있다.

1. **printStackTrace()** : 예외발생 당시의 호출스택(Call Stack)에 있었던 메서드 정보와 예외 메세디를 화면에 출력
2. **getMessage()** : 발생한 예외클래스의 인스턴스에 저장된 메시지를 얻을 수 있다.

```java
class ExceptionEx8 {
  public static void main(String args[]) {
    System.out.println(1);
    System.out.println(2);
    try{
      System.out.println(3);
    	System.out.println(0/0);
    	System.out.println(4);
    } catch (ArithmeticException ae) {
      ae.printStackTrace();
      System.out.println("예외 메시지 : " + ae.getMessage());
    }
    System.out.println(6);
  }
}
/*
출력 :
1
2
3
java.lang.ArithmeticException: / by zero
        at ExceptionEx8.main(ExceptionEx8.java:7)
예외 메서지 : / by zero
6
*/
```

이 예제는 앞서 말한 두 메서드를 사용한 예제이다. 보면 catch문을 제대로 수행하여 예외를 처리했으며 정상적으로 종료됫음을 알 수 있다.

위와 같이 사용하는 이유는 직접 저런식으로 호출 함으로써 어떠한 오류가 나타났는지 알 수 있게된다.

**2. 멀티 catch블럭**

지금까지 했던 여러 catch블럭을 '|'기호로 하나로 합칠 수 있는데 이를 멀티 catch블럭이라 부른다. 또한 합칠 수 있는 예외 클래스의 개수는 제한이 없다.

```java
try{
  ...
}catch(ExceptionA e){
  ...
}catch(ExceptionB e2){
  ...
}
```

위 코드는 우리가 지금껏 예외를 처리해온 방법이다.

```java
try{
  ...
}catch(ExceptionA | ExceptionB e){
  ...
}
```

위 코드는 멀티 catch블럭을 이용한 예외처리 방법이다.

그러나 위와 같이 멀티catch블럭을 사용하지 못하는 경우가 존제하는데 그 경우는 바로 멀티catch문을 사용한 두 클래스가 서로 상속관계에 있을 때이다. 

```java
try{
  ...
}catch(ParentException | ChildException e){    //에러
  ...
}
```

위와 같이 작성하면 분명 에러가 발생할 텐데 이는 굳이 저렇게 하지 않고 catch문의 괄호안에 부모클래스로 해놓으면 되기 때문이다.

```java
try{
  ...
}catch(ParentException e){
  ...
}
```

이 코드와 위 코드는 사실 다르게 없기 때문에 쓸모없는 코드를 줄이라는 의미의 에러이다.

멀티 catch블럭은 사실 하나의 참조변수를 이용해 여러 예외클래스를 처리하는 것이기 때문에 예외를 처리하더라도 어떤 예외가 발생했는지 알 수 없다. 

이는 멀티 catch블럭을 사용하게 되면 모든 예외 클래스들의 부모클래스에 선언된 멤버만 사용이 가능하다.

```java
try{
  ...
}catch (ExceptionA | ExceptionB e){
  e.mthodA();    //에러 : ExceptionA에 선언된 메서드는 사용 불가
  
  if(e instanceof ExceptionA){
    ExceptionA e1 = (ExceptionA)e;
    e1.methodA();
  }else{
    ...
  }
  
  e.printStackTrace();
}
```

위 코드에서 알 수 있듯 그냥 e를 통해 ExceptionA의 메서드에 접근하는 것은 불가능하다 그렇기에 사용하기 위해서는 코드에서 알 수 있듯 instacneof연산자를 통해 사용하도록 할 수 있다.

### 6. 예외 발생시키기

키워드인 throw를 활용하여 프로그래머가 고의로 예외를 발생시킬 수 있으며, 방법은 아래의 순서를 따르면 된다.

1. **먼저, 연산자 new를 이용해서 발생시키려는 예외 클래스의 객체를 만든다음**

   ```java
   Exception e = new Exception("고의로 발생시킴");
   ```

2. **키워드 throw를 이용하여 예외를 발생 시킴**

   ```java
   throw e;
   ```

```java
class ExceptionEx9 {
  public static void main(String args[]){
   	try{
      Exception e = new Exception("고의로 발생시킴");
      throw e;
      //throw new Exception("고의로 발생시킴"); 위 두줄을 한줄로 줄일 수 있다
    }catch (Exception e) {
      System.out.println("에러 메시지 : " + e.getMessage());
      e.printStackTrace();
    }
    System.out.println("프로그램이 정상적으로 종료됨");
  }
}
/* 
출력 :
java.lang.Exception: 고의로 발생시킴
        at ExceptionEx9.main(ExceptionEx9.java:4)
프로그램이 정상적으로 종료됨
*/
```

Exception인스턴스를 생성할 때, 생성자에 String을 넣어 주면, 이 String이 인스턴스에 메시지로 저장된다. 이 메시지는 getMessage()로도 얻을 수 있다.

```java
class ExceptionEx10 {
  public static void main(String args[]){
    throw new Exception();    //고의로 발생시켜 본다.
  }
}
```

이 예제를 작성후에 컴파일을 하게되면 그냥 에러가 발생해 컴파일을 완료하지 못하게 된다. 즉, 위에서와 같이 Exception클래스들과 관련된 모든 코드를 예외처리 해주지 않으면 컴파일이 정상적으로 이루어지지 않는다.

```java
class ExceptionEx11 {
  public static void main(String args[]) {
    throw new RuntimeException();
  }
}
```

위 코드역시 컴파일과정에서 실패할것 같지만 컴파일은 정상적으로 이루어지고 프로그램이 정상적으로 끝나지 않고 종료될 것이다.(RuntimeException클래스들) 그 이유는 위 예외는 프로그래머의 실수 혹은 유저의 실수로 이루어 지는 예외이기 때문에 예외처리를 강제하지 않는다.

그러나 만약 RuntimeException에도 예외처리를 강제로 해주어야만 한다면 아래와 같이 모든 참조변수, 배열을 사용할 때마다 다음과 같이 예외처리를 해주어야 한다.

```java
try{
  int[] arr = new int[10];
  System.out.println(arr[0]);
}catch (ArrayIndexOutOfBoundsException ae) {
  ...
}
```

 컴파일러가 예외처리를 확인하지 않는 RuntimeException클래스들은 **'unchecked 예외'** 예외처리를 확인하는 Exception클래스들은 **'checked 예외'**라고 부른다.

### 7. 메서드에 예외 선언하기

예외를 처리하는 방법에는 try-catc문도 있지만 메서드에 예외를 선언하는 방법이 있다. 메서드에 예외를 선언하려면, 메서드의 선언부에 키워드 throws를 사용해서 메서드 내에서 발생할 수 있는 예외를 적어주면 되고, 예외가 여러가지일 경우에는 쉼표로 구분한다.

```java
void method() throws Exception1, Exception2, Exception3, ... ExceptionN {
  ...
}
```

만약 throws에 Exception클래스를 메서드에 선언하게 되면, 이 메서드는 모든 종류의 예외가 발생할 가능성이 있다는 것이다.

```java
void method() throws Exception{
  ...
}
```

이렇게 예외를 선언하면, 이 예외뿐만 아닌 그 자손타입의 예외까지도 발생할 수 있다는 점에 주의해야한다. 앞서 오버라이딩에서 살펴본 것과 같이, 오버라이딩할 때는 단순히 선언된 예외의 개수가 아니라 상속관계까지 고려해야 한다.

사실 예외를 메서드의 throws에 명시하는 것은 예외를 처리하는 것이 아니라, 예외가 발생할 가능성이 있는 메서드를 호출한 메서드에게 예외처리를 하도록 떠맡기는 것이다.

이때 예외처리를 하지 않고 메서드들을 따라 전달되다가 제일 마지막에 있는 main메서드에서도 예외처리가 된지않으면 main메서드마저 종료되어 프로그램이 전체가 종료되고 만다.

```java
class ExceptionEx12{
  public static void main(String args[]) {
    method1();
  }
  static void method1() throws Exception { method2(); }
  static void method2() throws Exception { throw new Exception(); }
}
/*
출력결과 :
java.lang.Exception
        at ExceptionEx12.method2(ExceptionEx12.java:11)
        at ExceptionEx12.method1(ExceptionEx12.java:7)
        at ExceptionEx12.main(ExceptionEx12.java:3)
*/
```

위 출력결과를 통해 다음 사실을 알 수 있다.

1. **예외가 발생했을 때, 모두 3개의 메서드(main, method1, method2)가 호출스택에 있었으며,**
2. **예외가 발생한 곳은 제일 위줄에 있는 method2()라는 것과**
3. **main메서드가 method1()을, 그리고 method1()은 method2()를 호출했다는 것을 알 수 있다.**

이를 통해 알 수 있듯 throws를 해놓은 것은 예외가 처리되는 것이 아닌 자신을 호출한 메서드에게 예외를 단순히 전달만 하여 언젠가는 try-catch문을 통해 예외 처리를 해줘야 할 것이다.

```java
class ExceptionEx13 {
  public static void main(String[] args) {
    method1();
  }
  static void method1() {
    try{
      throw new Exception();
    } catch (Exception e) {
      System.out.println("method1메서드에서 예외가 처리되었습니다.");
      e.printStackTrace();
    }
  }
}
/*
출력결과 :
method1메서드에서 예외가 처리되었습니다.
java.lang.Ecception
        at ExceptionEx13.method1(ExceptionEx13.java:8)
        at ExceptionEx13.main(ExceptionEx13.java:3)
*/
```

예외는 처리되었지, printStackTrace()를 통해 예외에 대한 정보를 화면에 출력했을 때 main메서드가 method1()을 호출했음을 알 수 있다.

```java
class ExceptionEx14 {
  public static void main(String args[]) {
    try{
      method1();
    } catch (Exception e) {
      System.out.println("main메서드에서 예외가 처리되었습니다.");
      e.printStackTrace();
    }
  }
  static void method1() throws Exception {
    throw new Exception();
  }
}
/*
출력결과 :
method1메서드에서 예외가 처리되었습니다.
java.lang.Ecception
        at ExceptionEx13.method1(ExceptionEx13.java:12)
        at ExceptionEx13.main(ExceptionEx13.java:4)
*/
```

두 코드 모두 main에서 method1을 호출 하며, method1에서 예외가 발생한다. 차이점은 예외 처리 방법이다. 첫번째 코드는 main으로 예외를 넘겨 main에서 처리하도록 만들었고, 두번째는 method1에서 예외를 처리해 main은 예외가 있었는지도 알지 못하는 상태가 되었다.

이처럼 예외를 넘겨줌으로써 main메서드에서 처리할 수 도 있고, method1()에서 예외를 처리할 수도 있으며 두개가 서로 나눠서 처리할 수 도있다.

```java
import java.io.*;

class ExceptionEx14 {
  public static void main(String args[]) {
    File f = createFile(args[0]);
    System.out.println(f.getName() + " 파일이 성공적으로 생성되었습니다.");
  }
  static File createFile(String fileName){
    try{
      if(fileName == null || fileName.equals(""))
        throw new Exception("파일이름이 유효하지 않습니다.");
    } catch (Exception e) {
      fileName = "제목없음.txt";
    } finally {
      File f = new File(fileName);
      createNewFile(f);
      return f;
    }
  }
  static void createNewFile(File f) {
    try {
      f.createNewFile();
    } catch (Exception e){
      
    }
  }
}
/*
seogeonhui@seogeoncBookPro src % java ExceptionEx14 ""
제목없음.txt 파일이 성공적으로 생성되었습니다.
seogeonhui@seogeoncBookPro src % java ExceptionEx14 "test.txt"
test.txt 파일이 성공적으로 생성되었습니다.
*/
```

위 예제는 예외가 발생한 코드에서 직접 예외를 처리하도록 되어있다. try문에서 만약 적절치 못한 파일이름이 입력되면 예외를 발생시켜 catch블럭으로가서 제목없음.txt로 이름을 바꾸고 finally문으로 fileName에 맞는 파일을 생성한다.

```java
import java.io.*;

class ExceptionEx16 {
  public static void main(String args[]) {
    try {
      File f = createFile(args[0]);
      System.out.println(f.getName() + " 파일이 성공적으로 생성되었습니다.");
    } catch (Exception e) {
      System.out.println(e.getMessage() + " 다시 입력해 주시기 바랍니다.");
    }
  }
  static File createdFile(String fileName) throws Exception {
    if(fileName==null || fileName.equals(""))
      throw new Exception("파일이 유효하지 않습니다.");
    File f = new File(fileName);
    f.createNewFile();
    return f;
  }
}
/*
출력결과 :
seogeonhui@seogeonhuiui-MacBookPro src % java ExceptionEx17 ""   
파일이 유효하지 않습니다. 다시 입력해 주시기 바랍니다.
seogeonhui@seogeonhuiui-MacBookPro src % java ExceptionEx17 "HelloWorld.txt"
HelloWorld.txt 파일이 성공적으로 생성되었습니다.
seogeonhui@seogeonhuiui-MacBookPro src % 
*/
```

위 코드는 전과 달리 잘못입력된 파일이름을 임의로 처리하는 것이 아닌 호출한 main에게 예외를 알리고 다시 입력받도록 하였다. 

두 예제는 모두 커멘드라인에서 실행하여 파일이름을 입력받아 파일을 생성하도록하고 파일 이름을 잘못 입력했을 때 예외가 발생하도록 되어 있다. 차이점은 예외 처리 방법이다. 첫번째 예제는 createFile메서드가 직접 예외처리를 하지만, 두번째 예제는 메서드를 호출한 main에서 예외처리를 하였다.

### 8. finally블럭

finally블럭은 예외의 발생여부에 상관없이 실행되어야할 코드를 포함시킬 목적으로 사용된다. Try-catch문의 끝에 선택적으로 덧붙여 사용할 수 있으며, try-catch문의 끝에 선택적으로 덧붙여 사용할 수 있다.

```java
try {
  ...
} catch (Exception1 e1) {
  ...
} finally {
  ...
}
```

위와 같은 형태이며, try -> catch -> finally순으로 실행된다. 예외가 발생하지 않는다면, try -> finally다.

```java
class FinallyTest {
  public static void main(String args[]) {
    try {
      startInstall();
      copyFiles();
      deleteTempFiles();
    } catch (Exception e) {
      e.printStackTrace();
      deleteTempFiles();
    }
  }
  static void startInstall() {
    //프로그램 설치
  }
  static void copyFile() {
    //파일 복사
  }
  static void deleteTempFiles() {
    //임시파일 삭제
  }
}
```

위 예제는 프로그램 설치를 위한 준비를 하고 팡일들을 복사한뒤 설치가 완료되면, 설치하는데 사용했던 임시파일들을 순서대로 삭제한다. 위 코드는 실행중에 어느때든 예외가 발생하든 안하든 deleteTimeFiles()메서드를 매번 실행해야한다. 이때 다음과 같이 코드를 짜주면 된다.

```java
class FinallyTest2 {
  public static void main(String args[]) {
    try {
      startInstall();
      copyFiles();
    } catch (Exception e) {
      e.printStackTrace();
    } finally {
      deleteTempFiles();
    }
  }
  static void startInstall() {
    //프로그램 설치
  }
  static void copyFile() {
    //파일 복사
  }
  static void deleteTempFiles() {
    //임시파일 삭제
  }
}
```

이때 finally문은 try에서 return이 나오더라도 finally블럭을 먼저 실행한뒤 return을 실행한다.

```java
class FinallyTest3 {
  public static void main(String args[]){
    FinallyTest3.method1();
    System.out.println("method1()의 수행을 마치고 main으로 옴");
  }
  static void method1() {
    try{
      System.out.println("method1()이 호풀되었음");
      return;
    } catch (Exception e){
      e.printStackTrace();
    } finally {
      System.out.println("method1()의 finally블럭이 실행되었음");
    }
  }
}
/*
출력결과 :
method1()의 수행을 마치고 main으로 옴
method1()의 finally블럭이 실행되었음
method1()이 호풀되었음
*/
```

위와같이 return문이 실행되기전 finally블럭이 실행이 된다.

---



