# 예외처리(exception handling)

---

### 1. 프로그램 오류

프로그램이 실행 중 어떤 원인에 의해 오작동을 하거나 비정상적으로 종료되는 경우가 있다. 이러한 결과를 초래하는 원인을 프로그램 에러 또는 오류라고 한다.

에러는 발생 시점에 따라 종류가 나뉜다.

1. **컴파일 에러** : 컴파일 시에 발생하는 에러
2. **런타임 에러** : 실행 시에 발생하는 에러
3. **논리적 에러** : 실행은 되지만, 의도와 다르게 동작하는 것

간단하게 말하자면 대부분의 오류는 컴파일시 모두 걸러주지만 실행 도중 발생하는 에러인 런타임 에러를 방지하기 위해 실행도중 발생할 수 있는 모든 경우의 수를 고려하여 이에대한 대바가 필요하다는 것이 요점이다.

이때 실행시 발생할 수 있는 프로그램 오류를 **'에러(error)'**와 **'예외(exception)'**, 두 가지로 구분된다.

1. **에러(error)** : 프로그램 코드에 의해서 수습될 수 없는 심각한 오류
2. **예외(exception)** : 프로그램 코드에 의해서 수습될 수 있는 다소 미약한 오류

### 2. 예외 클래스의 계층 구조

자바는 실핼 시 발생할 수 있는 오류를 클래스로 정의 하였다. 우선 전에도 말했듯 모든 클래스의 부모은 당연히 Object이다. Exception과 Error클래스는 당연히 Object의 자손일 것이다.

모든 예외의 최고 조상은 예외(Exception)클래스이며, 예외의 자손들은 크게 두가지로 나뉠 수 있다.

1. **Exception클래스와 그 자손들(RuntimeException제외)**
2. **RuntimeException클래스와 그 자손들**

다음은 예외 클래스의 계층도를 나타내 본것이다.

- **Object**
  - Throwable
    - **Exception**
      - RuntimeException
      - IOException
      - ...
    - **Error**
      - OutOfMemoryError
      - ...

다음은 Exception과 RuntimeException을 기준으로 중심의 심층 계층도를 나타내본 것이다.

* **Exception**
  * IOExeption
  * ClassNotFoundException
  * ...
  * **RuntimeException**
    * ArithmeticException
    * ClassCastException
    * NullPointerException
    * ...
    * IndexOutBoundException

이렇게 둘로 나뉘는데 위와같이 Exception클래스의 자손들을 모아놓은 것을 **'Exception클래스들'** 또한 RuntimeException과 그 자손들을 모아 **'RuntimeException클래스들'**이라고 부른다.

1. **Exception클래스들** : 사용자의 실수와 같은 외적인 요인에 의해 발생하는 예외
2. **RuntimeException클래스들** : 프로그래머의 실수로 발생하는 예외

### 3. 예외처리하기 -try-catch문

예외처리(Exception Handling)란 무엇일까?

1. **정의** : 프로그램 발생 시 발생할 수 있는 예외에 대비한 코드를 작성하는 것
2. **목적** : 프로그램의 비정상 종료를 막고, 정상적인 실행상태를 유지하는 것.

발생한 예외를 처리하지 않으면, 프로그램은 비정상적으로 종료되며, 처리되지 못한 예외(uncaught exception)는 JVM의  **'예외처리기(UncaughtExceptionHandler)'**가 받아서 예외의 원인을 화면에 출력.

예외처리에는 보통 try-catch문을 사용한다.

```java
try {
  //예외가 발생할 가능성이 있는 문장들을 넣는다
} catch(Exception1 e1) {
  //Exception1이 발생했을 경우, 이를처리하기 위한 문장을 적는다.
} catch(Exception2 e2) {
  //Exception2이 발생했을 경우, 이를처리하기 위한 문장을 적는다.
} catch(Exception3 e3) {
  //''
}
```

```java
class ExceptionEx1 {
  public static void main(String args[]){
    try {
      try { } catch(Exception e) { }
    } catch(Exception e) {
      try { } catch(Exception e) { }
    }
    
    try {
      
    } catch(Exception e) {
      
    }
  }
}
```

위 코드는 단지 try-catch문이 중복으로도 사용될 수 있다는 것을 보여주는 코드이다. 

```java
class ExceptionEx2 {
  public static void main(String args[]) {
    int number = 100;
    int result = 0;
    
    for(int i = 0; i < 10; i++) {
      result = number / (int)(Math.random() * 10);    //7번쨰줄
      System.out.println(result);
    }
  }
}
//에러 발생 : 7번쨰줄에서 ArithmeticException 예외 발생
```

이 코드는 0~9중 임의의 수를 정수로 나눈 결과를 출력하는 일을 10번 반복하는 프로그램이다. 이때 실행 결과에 따라 다르겠지만 대부분은 10번출력하기 전에 비정상적으로 종료될 것이다.

그래서 결국 이 코드를 컴파일 한다면 주석에 써놨듯 ArithmeticException에러가 발생한다. 이 예외는 산술연산과정에서 오류가 났을때 발생하는 예외이며, 정수는 0으로 나누는 것이 금지되어 있어 발생되는 것이다.

이 코드를 예외처리 구문 try-catch문을 써서 다음과 같이 고칠 수 있다.

```java
class ExceptionEx3 {
  public static void main(String args[]) {
    int number = 100;
    int result = 0;
    
    for(int i = 0; i < 10; i++) {
      try{
        result = number / (int)(Math.random() * 10);
      	System.out.println(result);
      }catch (ArithmeticException e) {
        System.out.println("0");
      }//try-catch끝
    }//for문 종료
  }
}
/*
출력 :
16
20
11
0    =>    예외가 발생해 0출력
25
100
25
15
3
23
*/
```

### 4. Try-catch문애서의 흐름

Try-catch문에서, 예외가 발생한 경우와 발생하지 않았을 때의 흐름(문장의 실행순서)이 달라지는데, 아래의 이 두 가지 경우에 따른 문장 실행순서를 정리하였다.

1. **try블럭 내에서 예외가 발생한 경우**
   - 발생한 예외와 일치하는 catch블럭이 있는지 확인한다.
   - 일치하는 catch블럭을 찾게 되면, 그 catch블럭 내의 문장들을 수행하고 전체 try-catch문을 빠져나가서 그 다음 문장을 계속해서 수행 한다. 만일 일치하는 catch가 없다면 예외를 처리하지 못한다.
2. try블럭 내에서 예외가 발생하지 않은 경우,
   - catch블럭을 거치지 않고 전체 try-catch문을 빠져나가서 수행을 계속한다.

```java
class ExceptionEx4 {
  public static void main(String args[]) {
    System.out.println(1);
    System.out.println(2);
    try {
      System.out.println(3);
    	System.out.println(4);
    } catch (Exception e) {
      System.out.println(5);
    }
    System.out.println(6);
  }
}
/*
출력결과 :
1
2
3
4
6
*/
```

이 예제에서는 try문에서 예외가 발생하지 않았다. 그러므로 catch문이 실행되지 않았으므로 5가 스킵되고 6이 출력되는 것이다.

```java
class ExceptionEx4 {
  public static void main(String args[]) {
    System.out.println(1);
    System.out.println(2);
    try {
      System.out.println(3);
      System.out.println(0/0);    //0을 일부로 나누어 예외를 만듦
    	System.out.println(4);
    } catch (ArithmeticException ae) {
      System.out.println(5);
    }
    System.out.println(6);
  }
}
/*
출력결과 : 
1
2
3
5
6
*/
```

위 코드의 출력결과에서 알 수 있듯 만약 try문에서 예외가 발생하면 모든 수행을 멈추고 catch문을 실행한뒤 try-catch문을 빠져나간다.

---

